Watching for file changes with StatReloader
[25/Mar/2021 04:01:38] "GET / HTTP/1.1" 200 2996
[25/Mar/2021 04:01:58] "GET / HTTP/1.1" 200 2996
[25/Mar/2021 04:01:58] "GET / HTTP/1.1" 200 2996
[25/Mar/2021 04:02:01] "GET / HTTP/1.1" 200 2996
[25/Mar/2021 04:02:02] "GET /favicon.ico HTTP/1.1" 404 179
[25/Mar/2021 04:03:56] "GET / HTTP/1.1" 200 2996
[25/Mar/2021 04:03:57] "GET / HTTP/1.1" 200 2996
[25/Mar/2021 04:03:58] "GET / HTTP/1.1" 200 2996
[25/Mar/2021 04:04:09] "GET / HTTP/1.1" 200 2996
[25/Mar/2021 04:04:10] "GET /favicon.ico HTTP/1.1" 404 179
[25/Mar/2021 04:22:17] "GET / HTTP/1.1" 200 2996
[25/Mar/2021 05:24:38] "GET / HTTP/1.1" 200 2996
[25/Mar/2021 05:57:44] "GET / HTTP/1.1" 200 2996
----------------------------------------
Exception happened during processing of request from ('162.142.125.54', 60150)
Traceback (most recent call last):
  File "/home/ubuntu/anaconda3/lib/python3.7/socketserver.py", line 650, in process_request_thread
    self.finish_request(request, client_address)
  File "/home/ubuntu/anaconda3/lib/python3.7/socketserver.py", line 360, in finish_request
    self.RequestHandlerClass(request, client_address, self)
  File "/home/ubuntu/anaconda3/lib/python3.7/socketserver.py", line 720, in __init__
    self.handle()
  File "/home/ubuntu/anaconda3/lib/python3.7/site-packages/django/core/servers/basehttp.py", line 172, in handle
    self.handle_one_request()
  File "/home/ubuntu/anaconda3/lib/python3.7/site-packages/django/core/servers/basehttp.py", line 182, in handle_one_request
    self.raw_requestline = self.rfile.readline(65537)
  File "/home/ubuntu/anaconda3/lib/python3.7/socket.py", line 589, in readinto
    return self._sock.recv_into(b)
ConnectionResetError: [Errno 104] Connection reset by peer
----------------------------------------
[25/Mar/2021 17:19:17] code 400, message Bad request version ('À\x14À')
[25/Mar/2021 17:19:17] You're accessing the development server over HTTPS, but it only supports HTTP.

[25/Mar/2021 17:19:19] "GET / HTTP/1.1" 200 2996
----------------------------------------
Exception happened during processing of request from ('162.142.125.54', 48162)
Traceback (most recent call last):
  File "/home/ubuntu/anaconda3/lib/python3.7/socketserver.py", line 650, in process_request_thread
    self.finish_request(request, client_address)
  File "/home/ubuntu/anaconda3/lib/python3.7/socketserver.py", line 360, in finish_request
    self.RequestHandlerClass(request, client_address, self)
  File "/home/ubuntu/anaconda3/lib/python3.7/socketserver.py", line 720, in __init__
    self.handle()
  File "/home/ubuntu/anaconda3/lib/python3.7/site-packages/django/core/servers/basehttp.py", line 174, in handle
    self.handle_one_request()
  File "/home/ubuntu/anaconda3/lib/python3.7/site-packages/django/core/servers/basehttp.py", line 182, in handle_one_request
    self.raw_requestline = self.rfile.readline(65537)
  File "/home/ubuntu/anaconda3/lib/python3.7/socket.py", line 589, in readinto
    return self._sock.recv_into(b)
ConnectionResetError: [Errno 104] Connection reset by peer
----------------------------------------
[25/Mar/2021 17:19:19] "GET / HTTP/1.1" 200 2996
[25/Mar/2021 23:26:22] "GET / HTTP/1.1" 200 2996
[26/Mar/2021 00:34:28] "GET / HTTP/1.1" 200 2996
[26/Mar/2021 00:34:35] code 400, message Bad request version ('3#é±ú\x1b)\x91iÙÖ´\x96\x00$\x13\x01\x13\x03\x13\x02À+À/Ì©Ì¨À,À0À')
[26/Mar/2021 00:34:35] You're accessing the development server over HTTPS, but it only supports HTTP.

[26/Mar/2021 01:43:07] "GET / HTTP/1.1" 200 2996
[26/Mar/2021 01:43:08] "GET /favicon.ico HTTP/1.1" 404 179
[26/Mar/2021 03:10:50] "GET / HTTP/1.1" 200 2996
[26/Mar/2021 03:10:53] "GET /favicon.ico HTTP/1.1" 404 179
[26/Mar/2021 03:11:15] "GET / HTTP/1.1" 200 2996
[26/Mar/2021 03:11:15] "GET /favicon.ico HTTP/1.1" 404 179
[26/Mar/2021 03:11:26] "GET /favicon.ico HTTP/1.1" 404 179
Performing system checks...

System check identified no issues (0 silenced).

You have 18 unapplied migration(s). Your project may not work properly until you apply the migrations for app(s): admin, auth, contenttypes, sessions.
Run 'python manage.py migrate' to apply them.
March 25, 2021 - 04:01:29
Django version 3.1.3, using settings 'webForKDT.settings'
Starting development server at http://0.0.0.0:7999/
Quit the server with CONTROL-C.
[26/Mar/2021 03:24:01] "GET / HTTP/1.1" 200 3040
[26/Mar/2021 03:24:03] "GET /show_map HTTP/1.1" 500 145
[26/Mar/2021 03:24:12] "GET / HTTP/1.1" 200 3040
[26/Mar/2021 03:24:13] "GET /show_map HTTP/1.1" 500 145
[26/Mar/2021 03:24:27] "GET /show_map HTTP/1.1" 500 145
[2021-03-26 12:25:40 +0000] [30629] [INFO] Starting gunicorn 20.0.4
[2021-03-26 12:25:40 +0000] [30629] [INFO] Listening at: unix:/tmp/gunicorn.sock (30629)
[2021-03-26 12:25:40 +0000] [30629] [INFO] Using worker: sync
[2021-03-26 12:25:40 +0000] [30635] [INFO] Booting worker with pid: 30635
Internal Server Error: /show_map
Traceback (most recent call last):
  File "/home/ubuntu/anaconda3/lib/python3.7/site-packages/django/core/handlers/exception.py", line 47, in inner
    response = get_response(request)
  File "/home/ubuntu/anaconda3/lib/python3.7/site-packages/django/core/handlers/base.py", line 179, in _get_response
    response = wrapped_callback(request, *callback_args, **callback_kwargs)
  File "/home/ubuntu/a1/web/webForKDT/views.py", line 21, in webCapture_basic
    cv2.imwrite(file_name_path, frame)
cv2.error: OpenCV(4.5.1) /tmp/pip-req-build-7m_g9lbm/opencv/modules/imgcodecs/src/loadsave.cpp:753: error: (-215:Assertion failed) !_img.empty() in function 'imwrite'

[2021-03-26 12:51:06 +0000] [30629] [INFO] Handling signal: hup
[2021-03-26 12:51:06 +0000] [30629] [INFO] Hang up: Master
[2021-03-26 12:51:06 +0000] [3619] [INFO] Booting worker with pid: 3619
Internal Server Error: /show_map
Traceback (most recent call last):
  File "/home/ubuntu/anaconda3/lib/python3.7/site-packages/django/core/handlers/exception.py", line 47, in inner
    response = get_response(request)
  File "/home/ubuntu/anaconda3/lib/python3.7/site-packages/django/core/handlers/base.py", line 179, in _get_response
    response = wrapped_callback(request, *callback_args, **callback_kwargs)
  File "/home/ubuntu/a1/web/webForKDT/views.py", line 21, in webCapture_basic
    cv2.imwrite(file_name_path, frame)
cv2.error: OpenCV(4.5.1) /tmp/pip-req-build-7m_g9lbm/opencv/modules/imgcodecs/src/loadsave.cpp:753: error: (-215:Assertion failed) !_img.empty() in function 'imwrite'

Internal Server Error: /show_map
Traceback (most recent call last):
  File "/home/ubuntu/anaconda3/lib/python3.7/site-packages/django/core/handlers/exception.py", line 47, in inner
    response = get_response(request)
  File "/home/ubuntu/anaconda3/lib/python3.7/site-packages/django/core/handlers/base.py", line 179, in _get_response
    response = wrapped_callback(request, *callback_args, **callback_kwargs)
  File "/home/ubuntu/a1/web/webForKDT/views.py", line 21, in webCapture_basic
    cv2.imwrite(file_name_path, frame)
cv2.error: OpenCV(4.5.1) /tmp/pip-req-build-7m_g9lbm/opencv/modules/imgcodecs/src/loadsave.cpp:753: error: (-215:Assertion failed) !_img.empty() in function 'imwrite'

Not Found: /.env
Not Found: /v2/_catalog
Not Found: /graphql
Not Found: /info
Not Found: /.git/config
Not Found: /api/v1/pods
Internal Server Error: /show_map
Traceback (most recent call last):
  File "/home/ubuntu/anaconda3/lib/python3.7/site-packages/django/core/handlers/exception.py", line 47, in inner
    response = get_response(request)
  File "/home/ubuntu/anaconda3/lib/python3.7/site-packages/django/core/handlers/base.py", line 179, in _get_response
    response = wrapped_callback(request, *callback_args, **callback_kwargs)
  File "/home/ubuntu/a1/web/webForKDT/views.py", line 21, in webCapture_basic
cv2.error: OpenCV(4.5.1) /tmp/pip-req-build-7m_g9lbm/opencv/modules/imgcodecs/src/loadsave.cpp:753: error: (-215:Assertion failed) !_img.empty() in function 'imwrite'

Internal Server Error: /show_map
Traceback (most recent call last):
  File "/home/ubuntu/anaconda3/lib/python3.7/site-packages/django/core/handlers/exception.py", line 47, in inner
    response = get_response(request)
  File "/home/ubuntu/anaconda3/lib/python3.7/site-packages/django/core/handlers/base.py", line 179, in _get_response
    response = wrapped_callback(request, *callback_args, **callback_kwargs)
  File "/home/ubuntu/a1/web/webForKDT/views.py", line 21, in webCapture_basic
cv2.error: OpenCV(4.5.1) /tmp/pip-req-build-7m_g9lbm/opencv/modules/imgcodecs/src/loadsave.cpp:753: error: (-215:Assertion failed) !_img.empty() in function 'imwrite'

Internal Server Error: /show_map
Traceback (most recent call last):
  File "/home/ubuntu/anaconda3/lib/python3.7/site-packages/django/core/handlers/exception.py", line 47, in inner
    response = get_response(request)
  File "/home/ubuntu/anaconda3/lib/python3.7/site-packages/django/core/handlers/base.py", line 179, in _get_response
    response = wrapped_callback(request, *callback_args, **callback_kwargs)
  File "/home/ubuntu/a1/web/webForKDT/views.py", line 21, in webCapture_basic
cv2.error: OpenCV(4.5.1) /tmp/pip-req-build-7m_g9lbm/opencv/modules/imgcodecs/src/loadsave.cpp:753: error: (-215:Assertion failed) !_img.empty() in function 'imwrite'

[2021-03-26 13:32:35 +0000] [30629] [INFO] Handling signal: term
[2021-03-26 13:32:35 +0000] [3619] [INFO] Worker exiting (pid: 3619)
[2021-03-26 13:32:35 +0000] [30629] [INFO] Shutting down: Master
[2021-03-26 13:33:00 +0000] [13166] [INFO] Starting gunicorn 20.0.4
[2021-03-26 13:33:00 +0000] [13166] [INFO] Listening at: unix:/tmp/gunicorn.sock (13166)
[2021-03-26 13:33:00 +0000] [13166] [INFO] Using worker: sync
[2021-03-26 13:33:00 +0000] [13169] [INFO] Booting worker with pid: 13169
[2021-03-26 13:33:04 +0000] [13166] [INFO] Handling signal: int
[2021-03-26 13:33:05 +0000] [13169] [INFO] Worker exiting (pid: 13169)
[2021-03-26 13:33:05 +0000] [13166] [INFO] Shutting down: Master
[2021-03-26 13:33:11 +0000] [13205] [INFO] Starting gunicorn 20.0.4
[2021-03-26 13:33:11 +0000] [13205] [INFO] Listening at: unix:/tmp/gunicorn.sock (13205)
[2021-03-26 13:33:11 +0000] [13205] [INFO] Using worker: sync
[2021-03-26 13:33:11 +0000] [13208] [INFO] Booting worker with pid: 13208
Internal Server Error: /
Traceback (most recent call last):
  File "/home/ubuntu/anaconda3/lib/python3.7/site-packages/django/core/handlers/exception.py", line 47, in inner
    response = get_response(request)
  File "/home/ubuntu/anaconda3/lib/python3.7/site-packages/django/core/handlers/base.py", line 165, in _get_response
    callback, callback_args, callback_kwargs = self.resolve_request(request)
  File "/home/ubuntu/anaconda3/lib/python3.7/site-packages/django/core/handlers/base.py", line 288, in resolve_request
    resolver_match = resolver.resolve(request.path_info)
  File "/home/ubuntu/anaconda3/lib/python3.7/site-packages/django/urls/resolvers.py", line 545, in resolve
    for pattern in self.url_patterns:
  File "/home/ubuntu/anaconda3/lib/python3.7/site-packages/django/utils/functional.py", line 48, in __get__
    res = instance.__dict__[self.name] = self.func(instance)
  File "/home/ubuntu/anaconda3/lib/python3.7/site-packages/django/urls/resolvers.py", line 589, in url_patterns
    patterns = getattr(self.urlconf_module, "urlpatterns", self.urlconf_module)
  File "/home/ubuntu/anaconda3/lib/python3.7/site-packages/django/utils/functional.py", line 48, in __get__
    res = instance.__dict__[self.name] = self.func(instance)
  File "/home/ubuntu/anaconda3/lib/python3.7/site-packages/django/urls/resolvers.py", line 582, in urlconf_module
    return import_module(self.urlconf_name)
  File "/home/ubuntu/anaconda3/lib/python3.7/importlib/__init__.py", line 127, in import_module
    return _bootstrap._gcd_import(name[level:], package, level)
  File "<frozen importlib._bootstrap>", line 1006, in _gcd_import
  File "<frozen importlib._bootstrap>", line 983, in _find_and_load
  File "<frozen importlib._bootstrap>", line 967, in _find_and_load_unlocked
  File "<frozen importlib._bootstrap>", line 677, in _load_unlocked
  File "<frozen importlib._bootstrap_external>", line 728, in exec_module
  File "<frozen importlib._bootstrap>", line 219, in _call_with_frames_removed
  File "/home/ubuntu/a1/web/webForKDT/urls.py", line 18, in <module>
    from . import views
  File "/home/ubuntu/a1/web/webForKDT/views.py", line 19
    if not ret:
              ^
TabError: inconsistent use of tabs and spaces in indentation
Internal Server Error: /
Traceback (most recent call last):
  File "/home/ubuntu/anaconda3/lib/python3.7/site-packages/django/core/handlers/exception.py", line 47, in inner
    response = get_response(request)
  File "/home/ubuntu/anaconda3/lib/python3.7/site-packages/django/core/handlers/base.py", line 165, in _get_response
    callback, callback_args, callback_kwargs = self.resolve_request(request)
  File "/home/ubuntu/anaconda3/lib/python3.7/site-packages/django/core/handlers/base.py", line 288, in resolve_request
    resolver_match = resolver.resolve(request.path_info)
  File "/home/ubuntu/anaconda3/lib/python3.7/site-packages/django/urls/resolvers.py", line 545, in resolve
    for pattern in self.url_patterns:
  File "/home/ubuntu/anaconda3/lib/python3.7/site-packages/django/utils/functional.py", line 48, in __get__
    res = instance.__dict__[self.name] = self.func(instance)
  File "/home/ubuntu/anaconda3/lib/python3.7/site-packages/django/urls/resolvers.py", line 589, in url_patterns
    patterns = getattr(self.urlconf_module, "urlpatterns", self.urlconf_module)
  File "/home/ubuntu/anaconda3/lib/python3.7/site-packages/django/utils/functional.py", line 48, in __get__
    res = instance.__dict__[self.name] = self.func(instance)
  File "/home/ubuntu/anaconda3/lib/python3.7/site-packages/django/urls/resolvers.py", line 582, in urlconf_module
    return import_module(self.urlconf_name)
  File "/home/ubuntu/anaconda3/lib/python3.7/importlib/__init__.py", line 127, in import_module
    return _bootstrap._gcd_import(name[level:], package, level)
  File "<frozen importlib._bootstrap>", line 1006, in _gcd_import
  File "<frozen importlib._bootstrap>", line 983, in _find_and_load
  File "<frozen importlib._bootstrap>", line 967, in _find_and_load_unlocked
  File "<frozen importlib._bootstrap>", line 677, in _load_unlocked
  File "<frozen importlib._bootstrap_external>", line 728, in exec_module
  File "<frozen importlib._bootstrap>", line 219, in _call_with_frames_removed
  File "/home/ubuntu/a1/web/webForKDT/urls.py", line 18, in <module>
    from . import views
  File "/home/ubuntu/a1/web/webForKDT/views.py", line 19
    if not ret:
              ^
TabError: inconsistent use of tabs and spaces in indentation
[2021-03-26 13:34:16 +0000] [13205] [INFO] Handling signal: term
[2021-03-26 13:34:16 +0000] [13208] [INFO] Worker exiting (pid: 13208)
[2021-03-26 13:34:16 +0000] [13205] [INFO] Shutting down: Master
[2021-03-26 13:35:24 +0000] [13972] [INFO] Starting gunicorn 20.0.4
[2021-03-26 13:35:24 +0000] [13972] [INFO] Listening at: unix:/tmp/gunicorn.sock (13972)
[2021-03-26 13:35:24 +0000] [13972] [INFO] Using worker: sync
[2021-03-26 13:35:24 +0000] [13978] [INFO] Booting worker with pid: 13978
Internal Server Error: /
Traceback (most recent call last):
  File "/home/ubuntu/anaconda3/lib/python3.7/site-packages/django/core/handlers/exception.py", line 47, in inner
    response = get_response(request)
  File "/home/ubuntu/anaconda3/lib/python3.7/site-packages/django/core/handlers/base.py", line 165, in _get_response
    callback, callback_args, callback_kwargs = self.resolve_request(request)
  File "/home/ubuntu/anaconda3/lib/python3.7/site-packages/django/core/handlers/base.py", line 288, in resolve_request
    resolver_match = resolver.resolve(request.path_info)
  File "/home/ubuntu/anaconda3/lib/python3.7/site-packages/django/urls/resolvers.py", line 545, in resolve
    for pattern in self.url_patterns:
  File "/home/ubuntu/anaconda3/lib/python3.7/site-packages/django/utils/functional.py", line 48, in __get__
    res = instance.__dict__[self.name] = self.func(instance)
  File "/home/ubuntu/anaconda3/lib/python3.7/site-packages/django/urls/resolvers.py", line 589, in url_patterns
    patterns = getattr(self.urlconf_module, "urlpatterns", self.urlconf_module)
  File "/home/ubuntu/anaconda3/lib/python3.7/site-packages/django/utils/functional.py", line 48, in __get__
    res = instance.__dict__[self.name] = self.func(instance)
  File "/home/ubuntu/anaconda3/lib/python3.7/site-packages/django/urls/resolvers.py", line 582, in urlconf_module
    return import_module(self.urlconf_name)
  File "/home/ubuntu/anaconda3/lib/python3.7/importlib/__init__.py", line 127, in import_module
    return _bootstrap._gcd_import(name[level:], package, level)
  File "<frozen importlib._bootstrap>", line 1006, in _gcd_import
  File "<frozen importlib._bootstrap>", line 983, in _find_and_load
  File "<frozen importlib._bootstrap>", line 967, in _find_and_load_unlocked
  File "<frozen importlib._bootstrap>", line 677, in _load_unlocked
  File "<frozen importlib._bootstrap_external>", line 728, in exec_module
  File "<frozen importlib._bootstrap>", line 219, in _call_with_frames_removed
  File "/home/ubuntu/a1/web/webForKDT/urls.py", line 18, in <module>
    from . import views
  File "/home/ubuntu/a1/web/webForKDT/views.py", line 19
    if not ret:
              ^
TabError: inconsistent use of tabs and spaces in indentation
Internal Server Error: /
Traceback (most recent call last):
  File "/home/ubuntu/anaconda3/lib/python3.7/site-packages/django/core/handlers/exception.py", line 47, in inner
    response = get_response(request)
  File "/home/ubuntu/anaconda3/lib/python3.7/site-packages/django/core/handlers/base.py", line 165, in _get_response
    callback, callback_args, callback_kwargs = self.resolve_request(request)
  File "/home/ubuntu/anaconda3/lib/python3.7/site-packages/django/core/handlers/base.py", line 288, in resolve_request
    resolver_match = resolver.resolve(request.path_info)
  File "/home/ubuntu/anaconda3/lib/python3.7/site-packages/django/urls/resolvers.py", line 545, in resolve
    for pattern in self.url_patterns:
  File "/home/ubuntu/anaconda3/lib/python3.7/site-packages/django/utils/functional.py", line 48, in __get__
    res = instance.__dict__[self.name] = self.func(instance)
  File "/home/ubuntu/anaconda3/lib/python3.7/site-packages/django/urls/resolvers.py", line 589, in url_patterns
    patterns = getattr(self.urlconf_module, "urlpatterns", self.urlconf_module)
  File "/home/ubuntu/anaconda3/lib/python3.7/site-packages/django/utils/functional.py", line 48, in __get__
    res = instance.__dict__[self.name] = self.func(instance)
  File "/home/ubuntu/anaconda3/lib/python3.7/site-packages/django/urls/resolvers.py", line 582, in urlconf_module
    return import_module(self.urlconf_name)
  File "/home/ubuntu/anaconda3/lib/python3.7/importlib/__init__.py", line 127, in import_module
    return _bootstrap._gcd_import(name[level:], package, level)
  File "<frozen importlib._bootstrap>", line 1006, in _gcd_import
  File "<frozen importlib._bootstrap>", line 983, in _find_and_load
  File "<frozen importlib._bootstrap>", line 967, in _find_and_load_unlocked
  File "<frozen importlib._bootstrap>", line 677, in _load_unlocked
  File "<frozen importlib._bootstrap_external>", line 728, in exec_module
  File "<frozen importlib._bootstrap>", line 219, in _call_with_frames_removed
  File "/home/ubuntu/a1/web/webForKDT/urls.py", line 18, in <module>
    from . import views
  File "/home/ubuntu/a1/web/webForKDT/views.py", line 19
    if not ret:
              ^
TabError: inconsistent use of tabs and spaces in indentation
Internal Server Error: /
Traceback (most recent call last):
  File "/home/ubuntu/anaconda3/lib/python3.7/site-packages/django/core/handlers/exception.py", line 47, in inner
    response = get_response(request)
  File "/home/ubuntu/anaconda3/lib/python3.7/site-packages/django/core/handlers/base.py", line 165, in _get_response
    callback, callback_args, callback_kwargs = self.resolve_request(request)
  File "/home/ubuntu/anaconda3/lib/python3.7/site-packages/django/core/handlers/base.py", line 288, in resolve_request
    resolver_match = resolver.resolve(request.path_info)
  File "/home/ubuntu/anaconda3/lib/python3.7/site-packages/django/urls/resolvers.py", line 545, in resolve
    for pattern in self.url_patterns:
  File "/home/ubuntu/anaconda3/lib/python3.7/site-packages/django/utils/functional.py", line 48, in __get__
    res = instance.__dict__[self.name] = self.func(instance)
  File "/home/ubuntu/anaconda3/lib/python3.7/site-packages/django/urls/resolvers.py", line 589, in url_patterns
    patterns = getattr(self.urlconf_module, "urlpatterns", self.urlconf_module)
  File "/home/ubuntu/anaconda3/lib/python3.7/site-packages/django/utils/functional.py", line 48, in __get__
    res = instance.__dict__[self.name] = self.func(instance)
  File "/home/ubuntu/anaconda3/lib/python3.7/site-packages/django/urls/resolvers.py", line 582, in urlconf_module
    return import_module(self.urlconf_name)
  File "/home/ubuntu/anaconda3/lib/python3.7/importlib/__init__.py", line 127, in import_module
    return _bootstrap._gcd_import(name[level:], package, level)
  File "<frozen importlib._bootstrap>", line 1006, in _gcd_import
  File "<frozen importlib._bootstrap>", line 983, in _find_and_load
  File "<frozen importlib._bootstrap>", line 967, in _find_and_load_unlocked
  File "<frozen importlib._bootstrap>", line 677, in _load_unlocked
  File "<frozen importlib._bootstrap_external>", line 728, in exec_module
  File "<frozen importlib._bootstrap>", line 219, in _call_with_frames_removed
  File "/home/ubuntu/a1/web/webForKDT/urls.py", line 18, in <module>
    from . import views
  File "/home/ubuntu/a1/web/webForKDT/views.py", line 19
    if not ret:
              ^
TabError: inconsistent use of tabs and spaces in indentation
Internal Server Error: /
Traceback (most recent call last):
  File "/home/ubuntu/anaconda3/lib/python3.7/site-packages/django/core/handlers/exception.py", line 47, in inner
    response = get_response(request)
  File "/home/ubuntu/anaconda3/lib/python3.7/site-packages/django/core/handlers/base.py", line 165, in _get_response
    callback, callback_args, callback_kwargs = self.resolve_request(request)
  File "/home/ubuntu/anaconda3/lib/python3.7/site-packages/django/core/handlers/base.py", line 288, in resolve_request
    resolver_match = resolver.resolve(request.path_info)
  File "/home/ubuntu/anaconda3/lib/python3.7/site-packages/django/urls/resolvers.py", line 545, in resolve
    for pattern in self.url_patterns:
  File "/home/ubuntu/anaconda3/lib/python3.7/site-packages/django/utils/functional.py", line 48, in __get__
    res = instance.__dict__[self.name] = self.func(instance)
  File "/home/ubuntu/anaconda3/lib/python3.7/site-packages/django/urls/resolvers.py", line 589, in url_patterns
    patterns = getattr(self.urlconf_module, "urlpatterns", self.urlconf_module)
  File "/home/ubuntu/anaconda3/lib/python3.7/site-packages/django/utils/functional.py", line 48, in __get__
    res = instance.__dict__[self.name] = self.func(instance)
  File "/home/ubuntu/anaconda3/lib/python3.7/site-packages/django/urls/resolvers.py", line 582, in urlconf_module
    return import_module(self.urlconf_name)
  File "/home/ubuntu/anaconda3/lib/python3.7/importlib/__init__.py", line 127, in import_module
    return _bootstrap._gcd_import(name[level:], package, level)
  File "<frozen importlib._bootstrap>", line 1006, in _gcd_import
  File "<frozen importlib._bootstrap>", line 983, in _find_and_load
  File "<frozen importlib._bootstrap>", line 967, in _find_and_load_unlocked
  File "<frozen importlib._bootstrap>", line 677, in _load_unlocked
  File "<frozen importlib._bootstrap_external>", line 728, in exec_module
  File "<frozen importlib._bootstrap>", line 219, in _call_with_frames_removed
  File "/home/ubuntu/a1/web/webForKDT/urls.py", line 18, in <module>
    from . import views
  File "/home/ubuntu/a1/web/webForKDT/views.py", line 19
    if not ret:
              ^
TabError: inconsistent use of tabs and spaces in indentation
Internal Server Error: /
Traceback (most recent call last):
  File "/home/ubuntu/anaconda3/lib/python3.7/site-packages/django/core/handlers/exception.py", line 47, in inner
    response = get_response(request)
  File "/home/ubuntu/anaconda3/lib/python3.7/site-packages/django/core/handlers/base.py", line 165, in _get_response
    callback, callback_args, callback_kwargs = self.resolve_request(request)
  File "/home/ubuntu/anaconda3/lib/python3.7/site-packages/django/core/handlers/base.py", line 288, in resolve_request
    resolver_match = resolver.resolve(request.path_info)
  File "/home/ubuntu/anaconda3/lib/python3.7/site-packages/django/urls/resolvers.py", line 545, in resolve
    for pattern in self.url_patterns:
  File "/home/ubuntu/anaconda3/lib/python3.7/site-packages/django/utils/functional.py", line 48, in __get__
    res = instance.__dict__[self.name] = self.func(instance)
  File "/home/ubuntu/anaconda3/lib/python3.7/site-packages/django/urls/resolvers.py", line 589, in url_patterns
    patterns = getattr(self.urlconf_module, "urlpatterns", self.urlconf_module)
  File "/home/ubuntu/anaconda3/lib/python3.7/site-packages/django/utils/functional.py", line 48, in __get__
    res = instance.__dict__[self.name] = self.func(instance)
  File "/home/ubuntu/anaconda3/lib/python3.7/site-packages/django/urls/resolvers.py", line 582, in urlconf_module
    return import_module(self.urlconf_name)
  File "/home/ubuntu/anaconda3/lib/python3.7/importlib/__init__.py", line 127, in import_module
    return _bootstrap._gcd_import(name[level:], package, level)
  File "<frozen importlib._bootstrap>", line 1006, in _gcd_import
  File "<frozen importlib._bootstrap>", line 983, in _find_and_load
  File "<frozen importlib._bootstrap>", line 967, in _find_and_load_unlocked
  File "<frozen importlib._bootstrap>", line 677, in _load_unlocked
  File "<frozen importlib._bootstrap_external>", line 728, in exec_module
  File "<frozen importlib._bootstrap>", line 219, in _call_with_frames_removed
  File "/home/ubuntu/a1/web/webForKDT/urls.py", line 18, in <module>
    from . import views
  File "/home/ubuntu/a1/web/webForKDT/views.py", line 19
    if not ret:
              ^
TabError: inconsistent use of tabs and spaces in indentation
Internal Server Error: /
Traceback (most recent call last):
  File "/home/ubuntu/anaconda3/lib/python3.7/site-packages/django/core/handlers/exception.py", line 47, in inner
    response = get_response(request)
  File "/home/ubuntu/anaconda3/lib/python3.7/site-packages/django/core/handlers/base.py", line 165, in _get_response
    callback, callback_args, callback_kwargs = self.resolve_request(request)
  File "/home/ubuntu/anaconda3/lib/python3.7/site-packages/django/core/handlers/base.py", line 288, in resolve_request
    resolver_match = resolver.resolve(request.path_info)
  File "/home/ubuntu/anaconda3/lib/python3.7/site-packages/django/urls/resolvers.py", line 545, in resolve
    for pattern in self.url_patterns:
  File "/home/ubuntu/anaconda3/lib/python3.7/site-packages/django/utils/functional.py", line 48, in __get__
    res = instance.__dict__[self.name] = self.func(instance)
  File "/home/ubuntu/anaconda3/lib/python3.7/site-packages/django/urls/resolvers.py", line 589, in url_patterns
    patterns = getattr(self.urlconf_module, "urlpatterns", self.urlconf_module)
  File "/home/ubuntu/anaconda3/lib/python3.7/site-packages/django/utils/functional.py", line 48, in __get__
    res = instance.__dict__[self.name] = self.func(instance)
  File "/home/ubuntu/anaconda3/lib/python3.7/site-packages/django/urls/resolvers.py", line 582, in urlconf_module
    return import_module(self.urlconf_name)
  File "/home/ubuntu/anaconda3/lib/python3.7/importlib/__init__.py", line 127, in import_module
    return _bootstrap._gcd_import(name[level:], package, level)
  File "<frozen importlib._bootstrap>", line 1006, in _gcd_import
  File "<frozen importlib._bootstrap>", line 983, in _find_and_load
  File "<frozen importlib._bootstrap>", line 967, in _find_and_load_unlocked
  File "<frozen importlib._bootstrap>", line 677, in _load_unlocked
  File "<frozen importlib._bootstrap_external>", line 728, in exec_module
  File "<frozen importlib._bootstrap>", line 219, in _call_with_frames_removed
  File "/home/ubuntu/a1/web/webForKDT/urls.py", line 18, in <module>
    from . import views
  File "/home/ubuntu/a1/web/webForKDT/views.py", line 19
    if not ret:
              ^
TabError: inconsistent use of tabs and spaces in indentation
Internal Server Error: /
Traceback (most recent call last):
  File "/home/ubuntu/anaconda3/lib/python3.7/site-packages/django/core/handlers/exception.py", line 47, in inner
    response = get_response(request)
  File "/home/ubuntu/anaconda3/lib/python3.7/site-packages/django/core/handlers/base.py", line 165, in _get_response
    callback, callback_args, callback_kwargs = self.resolve_request(request)
  File "/home/ubuntu/anaconda3/lib/python3.7/site-packages/django/core/handlers/base.py", line 288, in resolve_request
    resolver_match = resolver.resolve(request.path_info)
  File "/home/ubuntu/anaconda3/lib/python3.7/site-packages/django/urls/resolvers.py", line 545, in resolve
    for pattern in self.url_patterns:
  File "/home/ubuntu/anaconda3/lib/python3.7/site-packages/django/utils/functional.py", line 48, in __get__
    res = instance.__dict__[self.name] = self.func(instance)
  File "/home/ubuntu/anaconda3/lib/python3.7/site-packages/django/urls/resolvers.py", line 589, in url_patterns
    patterns = getattr(self.urlconf_module, "urlpatterns", self.urlconf_module)
  File "/home/ubuntu/anaconda3/lib/python3.7/site-packages/django/utils/functional.py", line 48, in __get__
    res = instance.__dict__[self.name] = self.func(instance)
  File "/home/ubuntu/anaconda3/lib/python3.7/site-packages/django/urls/resolvers.py", line 582, in urlconf_module
    return import_module(self.urlconf_name)
  File "/home/ubuntu/anaconda3/lib/python3.7/importlib/__init__.py", line 127, in import_module
    return _bootstrap._gcd_import(name[level:], package, level)
  File "<frozen importlib._bootstrap>", line 1006, in _gcd_import
  File "<frozen importlib._bootstrap>", line 983, in _find_and_load
  File "<frozen importlib._bootstrap>", line 967, in _find_and_load_unlocked
  File "<frozen importlib._bootstrap>", line 677, in _load_unlocked
  File "<frozen importlib._bootstrap_external>", line 728, in exec_module
  File "<frozen importlib._bootstrap>", line 219, in _call_with_frames_removed
  File "/home/ubuntu/a1/web/webForKDT/urls.py", line 18, in <module>
    from . import views
  File "/home/ubuntu/a1/web/webForKDT/views.py", line 19
    if not ret:
              ^
TabError: inconsistent use of tabs and spaces in indentation
Internal Server Error: /
Traceback (most recent call last):
  File "/home/ubuntu/anaconda3/lib/python3.7/site-packages/django/core/handlers/exception.py", line 47, in inner
    response = get_response(request)
  File "/home/ubuntu/anaconda3/lib/python3.7/site-packages/django/core/handlers/base.py", line 165, in _get_response
    callback, callback_args, callback_kwargs = self.resolve_request(request)
  File "/home/ubuntu/anaconda3/lib/python3.7/site-packages/django/core/handlers/base.py", line 288, in resolve_request
    resolver_match = resolver.resolve(request.path_info)
  File "/home/ubuntu/anaconda3/lib/python3.7/site-packages/django/urls/resolvers.py", line 545, in resolve
    for pattern in self.url_patterns:
  File "/home/ubuntu/anaconda3/lib/python3.7/site-packages/django/utils/functional.py", line 48, in __get__
    res = instance.__dict__[self.name] = self.func(instance)
  File "/home/ubuntu/anaconda3/lib/python3.7/site-packages/django/urls/resolvers.py", line 589, in url_patterns
    patterns = getattr(self.urlconf_module, "urlpatterns", self.urlconf_module)
  File "/home/ubuntu/anaconda3/lib/python3.7/site-packages/django/utils/functional.py", line 48, in __get__
    res = instance.__dict__[self.name] = self.func(instance)
  File "/home/ubuntu/anaconda3/lib/python3.7/site-packages/django/urls/resolvers.py", line 582, in urlconf_module
    return import_module(self.urlconf_name)
  File "/home/ubuntu/anaconda3/lib/python3.7/importlib/__init__.py", line 127, in import_module
    return _bootstrap._gcd_import(name[level:], package, level)
  File "<frozen importlib._bootstrap>", line 1006, in _gcd_import
  File "<frozen importlib._bootstrap>", line 983, in _find_and_load
  File "<frozen importlib._bootstrap>", line 967, in _find_and_load_unlocked
  File "<frozen importlib._bootstrap>", line 677, in _load_unlocked
  File "<frozen importlib._bootstrap_external>", line 728, in exec_module
  File "<frozen importlib._bootstrap>", line 219, in _call_with_frames_removed
  File "/home/ubuntu/a1/web/webForKDT/urls.py", line 18, in <module>
    from . import views
  File "/home/ubuntu/a1/web/webForKDT/views.py", line 19
    if not ret:
              ^
TabError: inconsistent use of tabs and spaces in indentation
Internal Server Error: /
Traceback (most recent call last):
  File "/home/ubuntu/anaconda3/lib/python3.7/site-packages/django/core/handlers/exception.py", line 47, in inner
    response = get_response(request)
  File "/home/ubuntu/anaconda3/lib/python3.7/site-packages/django/core/handlers/base.py", line 165, in _get_response
    callback, callback_args, callback_kwargs = self.resolve_request(request)
  File "/home/ubuntu/anaconda3/lib/python3.7/site-packages/django/core/handlers/base.py", line 288, in resolve_request
    resolver_match = resolver.resolve(request.path_info)
  File "/home/ubuntu/anaconda3/lib/python3.7/site-packages/django/urls/resolvers.py", line 545, in resolve
    for pattern in self.url_patterns:
  File "/home/ubuntu/anaconda3/lib/python3.7/site-packages/django/utils/functional.py", line 48, in __get__
    res = instance.__dict__[self.name] = self.func(instance)
  File "/home/ubuntu/anaconda3/lib/python3.7/site-packages/django/urls/resolvers.py", line 589, in url_patterns
    patterns = getattr(self.urlconf_module, "urlpatterns", self.urlconf_module)
  File "/home/ubuntu/anaconda3/lib/python3.7/site-packages/django/utils/functional.py", line 48, in __get__
    res = instance.__dict__[self.name] = self.func(instance)
  File "/home/ubuntu/anaconda3/lib/python3.7/site-packages/django/urls/resolvers.py", line 582, in urlconf_module
    return import_module(self.urlconf_name)
  File "/home/ubuntu/anaconda3/lib/python3.7/importlib/__init__.py", line 127, in import_module
    return _bootstrap._gcd_import(name[level:], package, level)
  File "<frozen importlib._bootstrap>", line 1006, in _gcd_import
  File "<frozen importlib._bootstrap>", line 983, in _find_and_load
  File "<frozen importlib._bootstrap>", line 967, in _find_and_load_unlocked
  File "<frozen importlib._bootstrap>", line 677, in _load_unlocked
  File "<frozen importlib._bootstrap_external>", line 728, in exec_module
  File "<frozen importlib._bootstrap>", line 219, in _call_with_frames_removed
  File "/home/ubuntu/a1/web/webForKDT/urls.py", line 18, in <module>
    from . import views
  File "/home/ubuntu/a1/web/webForKDT/views.py", line 19
    if not ret:
              ^
TabError: inconsistent use of tabs and spaces in indentation
[2021-03-26 13:37:02 +0000] [13972] [INFO] Handling signal: term
[2021-03-26 13:37:02 +0000] [13978] [INFO] Worker exiting (pid: 13978)
[2021-03-26 13:37:02 +0000] [13972] [INFO] Shutting down: Master
[2021-03-26 13:37:06 +0000] [14318] [INFO] Starting gunicorn 20.0.4
[2021-03-26 13:37:06 +0000] [14318] [INFO] Listening at: unix:/tmp/gunicorn.sock (14318)
[2021-03-26 13:37:06 +0000] [14318] [INFO] Using worker: sync
[2021-03-26 13:37:06 +0000] [14324] [INFO] Booting worker with pid: 14324
Internal Server Error: /show_map
Traceback (most recent call last):
  File "/home/ubuntu/anaconda3/lib/python3.7/site-packages/django/core/handlers/exception.py", line 47, in inner
    response = get_response(request)
  File "/home/ubuntu/anaconda3/lib/python3.7/site-packages/django/core/handlers/base.py", line 179, in _get_response
    response = wrapped_callback(request, *callback_args, **callback_kwargs)
  File "/home/ubuntu/a1/web/webForKDT/views.py", line 35, in webCapture_basic
    files = open('static/img/capture_img/test1.jpg', 'rb').read()
FileNotFoundError: [Errno 2] No such file or directory: 'static/img/capture_img/test1.jpg'
Internal Server Error: /show_map
Traceback (most recent call last):
  File "/home/ubuntu/anaconda3/lib/python3.7/site-packages/django/core/handlers/exception.py", line 47, in inner
    response = get_response(request)
  File "/home/ubuntu/anaconda3/lib/python3.7/site-packages/django/core/handlers/base.py", line 179, in _get_response
    response = wrapped_callback(request, *callback_args, **callback_kwargs)
  File "/home/ubuntu/a1/web/webForKDT/views.py", line 35, in webCapture_basic
    files = open('static/img/capture_img/test1.jpg', 'rb').read()
FileNotFoundError: [Errno 2] No such file or directory: 'static/img/capture_img/test1.jpg'
[2021-03-26 13:39:32 +0000] [14318] [INFO] Handling signal: term
[2021-03-26 13:39:32 +0000] [14324] [INFO] Worker exiting (pid: 14324)
[2021-03-26 13:39:32 +0000] [14318] [INFO] Shutting down: Master
[2021-03-26 13:39:36 +0000] [14780] [INFO] Starting gunicorn 20.0.4
[2021-03-26 13:39:36 +0000] [14780] [INFO] Listening at: unix:/tmp/gunicorn.sock (14780)
[2021-03-26 13:39:36 +0000] [14780] [INFO] Using worker: sync
[2021-03-26 13:39:36 +0000] [14789] [INFO] Booting worker with pid: 14789
Internal Server Error: /show_map
Traceback (most recent call last):
  File "/home/ubuntu/anaconda3/lib/python3.7/site-packages/django/core/handlers/exception.py", line 47, in inner
    response = get_response(request)
  File "/home/ubuntu/anaconda3/lib/python3.7/site-packages/django/core/handlers/base.py", line 179, in _get_response
    response = wrapped_callback(request, *callback_args, **callback_kwargs)
  File "/home/ubuntu/a1/web/webForKDT/views.py", line 35, in webCapture_basic
    files = open('static/img/capture_img/test1.jpg', 'rb').read()
FileNotFoundError: [Errno 2] No such file or directory: 'static/img/capture_img/test1.jpg'
Internal Server Error: /show_map
Traceback (most recent call last):
  File "/home/ubuntu/anaconda3/lib/python3.7/site-packages/django/core/handlers/exception.py", line 47, in inner
    response = get_response(request)
  File "/home/ubuntu/anaconda3/lib/python3.7/site-packages/django/core/handlers/base.py", line 179, in _get_response
    response = wrapped_callback(request, *callback_args, **callback_kwargs)
  File "/home/ubuntu/a1/web/webForKDT/views.py", line 35, in webCapture_basic
    files = open('static/img/capture_img/test1.jpg', 'rb').read()
FileNotFoundError: [Errno 2] No such file or directory: 'static/img/capture_img/test1.jpg'
[2021-03-26 13:46:08 +0000] [14780] [INFO] Handling signal: term
[2021-03-26 13:46:08 +0000] [14789] [INFO] Worker exiting (pid: 14789)
[2021-03-26 13:46:08 +0000] [14780] [INFO] Shutting down: Master
[2021-03-26 13:46:11 +0000] [15986] [INFO] Starting gunicorn 20.0.4
[2021-03-26 13:46:11 +0000] [15986] [INFO] Listening at: unix:/tmp/gunicorn.sock (15986)
[2021-03-26 13:46:11 +0000] [15986] [INFO] Using worker: sync
[2021-03-26 13:46:11 +0000] [15989] [INFO] Booting worker with pid: 15989
[ WARN:0] global /tmp/pip-req-build-7m_g9lbm/opencv/modules/videoio/src/cap_v4l.cpp (893) open VIDEOIO(V4L2:/dev/video0): can't open camera by index
Internal Server Error: /show_map
Traceback (most recent call last):
  File "/home/ubuntu/anaconda3/lib/python3.7/site-packages/django/core/handlers/exception.py", line 47, in inner
    response = get_response(request)
  File "/home/ubuntu/anaconda3/lib/python3.7/site-packages/django/core/handlers/base.py", line 179, in _get_response
    response = wrapped_callback(request, *callback_args, **callback_kwargs)
  File "/home/ubuntu/a1/web/webForKDT/views.py", line 35, in webCapture_basic
    files = open('static/img/capture_img/test1.jpg', 'rb').read()
FileNotFoundError: [Errno 2] No such file or directory: 'static/img/capture_img/test1.jpg'
[2021-03-26 13:48:46 +0000] [15986] [INFO] Handling signal: term
[2021-03-26 13:48:46 +0000] [15989] [INFO] Worker exiting (pid: 15989)
[2021-03-26 13:48:46 +0000] [15986] [INFO] Shutting down: Master
[2021-03-26 13:48:50 +0000] [16482] [INFO] Starting gunicorn 20.0.4
[2021-03-26 13:48:50 +0000] [16482] [INFO] Listening at: unix:/tmp/gunicorn.sock (16482)
[2021-03-26 13:48:50 +0000] [16482] [INFO] Using worker: sync
[2021-03-26 13:48:50 +0000] [16485] [INFO] Booting worker with pid: 16485
[ WARN:0] global /tmp/pip-req-build-7m_g9lbm/opencv/modules/videoio/src/cap_v4l.cpp (893) open VIDEOIO(V4L2:/dev/video0): can't open camera by index
Internal Server Error: /show_map
Traceback (most recent call last):
  File "/home/ubuntu/anaconda3/lib/python3.7/site-packages/django/core/handlers/exception.py", line 47, in inner
    response = get_response(request)
  File "/home/ubuntu/anaconda3/lib/python3.7/site-packages/django/core/handlers/base.py", line 179, in _get_response
    response = wrapped_callback(request, *callback_args, **callback_kwargs)
  File "/home/ubuntu/a1/web/webForKDT/views.py", line 36, in webCapture_basic
    files = open('static/img/capture_img/test1.jpg', 'rb').read()
FileNotFoundError: [Errno 2] No such file or directory: 'static/img/capture_img/test1.jpg'
[ WARN:0] global /tmp/pip-req-build-7m_g9lbm/opencv/modules/videoio/src/cap_v4l.cpp (893) open VIDEOIO(V4L2:/dev/video0): can't open camera by index
Internal Server Error: /show_map
Traceback (most recent call last):
  File "/home/ubuntu/anaconda3/lib/python3.7/site-packages/django/core/handlers/exception.py", line 47, in inner
    response = get_response(request)
  File "/home/ubuntu/anaconda3/lib/python3.7/site-packages/django/core/handlers/base.py", line 179, in _get_response
    response = wrapped_callback(request, *callback_args, **callback_kwargs)
  File "/home/ubuntu/a1/web/webForKDT/views.py", line 36, in webCapture_basic
    files = open('static/img/capture_img/test1.jpg', 'rb').read()
FileNotFoundError: [Errno 2] No such file or directory: 'static/img/capture_img/test1.jpg'
[2021-03-26 13:54:28 +0000] [16482] [INFO] Handling signal: term
[2021-03-26 13:54:28 +0000] [16485] [INFO] Worker exiting (pid: 16485)
False (False, None)
False (False, None)
[2021-03-26 13:54:28 +0000] [16482] [INFO] Shutting down: Master
[2021-03-26 13:54:33 +0000] [17526] [INFO] Starting gunicorn 20.0.4
[2021-03-26 13:54:33 +0000] [17526] [INFO] Listening at: unix:/tmp/gunicorn.sock (17526)
[2021-03-26 13:54:33 +0000] [17526] [INFO] Using worker: sync
[2021-03-26 13:54:33 +0000] [17532] [INFO] Booting worker with pid: 17532
[ WARN:0] global /tmp/pip-req-build-7m_g9lbm/opencv/modules/videoio/src/cap_v4l.cpp (893) open VIDEOIO(V4L2:/dev/video0): can't open camera by index
Internal Server Error: /show_map
Traceback (most recent call last):
  File "/home/ubuntu/anaconda3/lib/python3.7/site-packages/django/core/handlers/exception.py", line 47, in inner
    response = get_response(request)
  File "/home/ubuntu/anaconda3/lib/python3.7/site-packages/django/core/handlers/base.py", line 179, in _get_response
    response = wrapped_callback(request, *callback_args, **callback_kwargs)
  File "/home/ubuntu/a1/web/webForKDT/views.py", line 35, in webCapture_basic
    files = open('static/img/capture_img/test1.jpg', 'rb').read()
FileNotFoundError: [Errno 2] No such file or directory: 'static/img/capture_img/test1.jpg'
[ WARN:0] global /tmp/pip-req-build-7m_g9lbm/opencv/modules/videoio/src/cap_v4l.cpp (893) open VIDEOIO(V4L2:/dev/video0): can't open camera by index
Internal Server Error: /show_map
Traceback (most recent call last):
  File "/home/ubuntu/anaconda3/lib/python3.7/site-packages/django/core/handlers/exception.py", line 47, in inner
    response = get_response(request)
  File "/home/ubuntu/anaconda3/lib/python3.7/site-packages/django/core/handlers/base.py", line 179, in _get_response
    response = wrapped_callback(request, *callback_args, **callback_kwargs)
  File "/home/ubuntu/a1/web/webForKDT/views.py", line 35, in webCapture_basic
    files = open('static/img/capture_img/test1.jpg', 'rb').read()
FileNotFoundError: [Errno 2] No such file or directory: 'static/img/capture_img/test1.jpg'
[2021-03-26 13:58:48 +0000] [17526] [INFO] Handling signal: term
[2021-03-26 13:58:48 +0000] [17532] [INFO] Worker exiting (pid: 17532)
[2021-03-26 13:58:49 +0000] [17526] [INFO] Shutting down: Master
[2021-03-26 13:58:51 +0000] [18310] [INFO] Starting gunicorn 20.0.4
[2021-03-26 13:58:51 +0000] [18310] [INFO] Listening at: unix:/tmp/gunicorn.sock (18310)
[2021-03-26 13:58:51 +0000] [18310] [INFO] Using worker: sync
[2021-03-26 13:58:51 +0000] [18316] [INFO] Booting worker with pid: 18316
[ WARN:0] global /tmp/pip-req-build-7m_g9lbm/opencv/modules/videoio/src/cap_v4l.cpp (880) open VIDEOIO(V4L2): can't find camera device
Internal Server Error: /show_map
Traceback (most recent call last):
  File "/home/ubuntu/anaconda3/lib/python3.7/site-packages/django/core/handlers/exception.py", line 47, in inner
    response = get_response(request)
  File "/home/ubuntu/anaconda3/lib/python3.7/site-packages/django/core/handlers/base.py", line 179, in _get_response
    response = wrapped_callback(request, *callback_args, **callback_kwargs)
  File "/home/ubuntu/a1/web/webForKDT/views.py", line 35, in webCapture_basic
    files = open('static/img/capture_img/test1.jpg', 'rb').read()
FileNotFoundError: [Errno 2] No such file or directory: 'static/img/capture_img/test1.jpg'
[ WARN:0] global /tmp/pip-req-build-7m_g9lbm/opencv/modules/videoio/src/cap_v4l.cpp (880) open VIDEOIO(V4L2): can't find camera device
Internal Server Error: /show_map
Traceback (most recent call last):
  File "/home/ubuntu/anaconda3/lib/python3.7/site-packages/django/core/handlers/exception.py", line 47, in inner
    response = get_response(request)
  File "/home/ubuntu/anaconda3/lib/python3.7/site-packages/django/core/handlers/base.py", line 179, in _get_response
    response = wrapped_callback(request, *callback_args, **callback_kwargs)
  File "/home/ubuntu/a1/web/webForKDT/views.py", line 35, in webCapture_basic
    files = open('static/img/capture_img/test1.jpg', 'rb').read()
FileNotFoundError: [Errno 2] No such file or directory: 'static/img/capture_img/test1.jpg'
[ WARN:0] global /tmp/pip-req-build-7m_g9lbm/opencv/modules/videoio/src/cap_v4l.cpp (880) open VIDEOIO(V4L2): can't find camera device
Internal Server Error: /show_map
Traceback (most recent call last):
  File "/home/ubuntu/anaconda3/lib/python3.7/site-packages/django/core/handlers/exception.py", line 47, in inner
    response = get_response(request)
  File "/home/ubuntu/anaconda3/lib/python3.7/site-packages/django/core/handlers/base.py", line 179, in _get_response
    response = wrapped_callback(request, *callback_args, **callback_kwargs)
  File "/home/ubuntu/a1/web/webForKDT/views.py", line 35, in webCapture_basic
    files = open('static/img/capture_img/test1.jpg', 'rb').read()
FileNotFoundError: [Errno 2] No such file or directory: 'static/img/capture_img/test1.jpg'
[ WARN:0] global /tmp/pip-req-build-7m_g9lbm/opencv/modules/videoio/src/cap_v4l.cpp (880) open VIDEOIO(V4L2): can't find camera device
Internal Server Error: /show_map
Traceback (most recent call last):
  File "/home/ubuntu/anaconda3/lib/python3.7/site-packages/django/core/handlers/exception.py", line 47, in inner
    response = get_response(request)
  File "/home/ubuntu/anaconda3/lib/python3.7/site-packages/django/core/handlers/base.py", line 179, in _get_response
    response = wrapped_callback(request, *callback_args, **callback_kwargs)
  File "/home/ubuntu/a1/web/webForKDT/views.py", line 35, in webCapture_basic
    files = open('static/img/capture_img/test1.jpg', 'rb').read()
FileNotFoundError: [Errno 2] No such file or directory: 'static/img/capture_img/test1.jpg'
